Workbook

Sheet Summary
A1: UPI Analyzer API — Test Execution Summary
A2: Status and bug cells in blue are inputs; everything below recalculates from the other sheets.
A4: Total test cases | B4: =COUNTA('Test Cases'!A2:A1000) -> 48
A5: Passed | B5: =COUNTIF('Test Cases'!I2:I1000,"Pass") -> 39
A6: Failed | B6: =COUNTIF('Test Cases'!I2:I1000,"Fail") -> 9
A7: Blocked / Not run | B7: =COUNTIF('Test Cases'!I2:I1000,"Blocked")+COUNTIF('Test Cases'!I2:I1000,"Not Run") -> 0
A8: Pass rate | B8: =IF(B4=0,0,B5/B4) -> 0.8125
A9: Defects logged | B9: =COUNTA(Defects!A2:A1000) -> 9
A10: Open defects | B10: =COUNTIF(Defects!F2:F1000,"Open")+COUNTIF(Defects!F2:F1000,"In Progress") -> 9
A11: Major defects | B11: =COUNTIF(Defects!C2:C1000,"Major") -> 5
A14: Results by module
A15: Module | B15: Cases | C15: Pass | D15: Fail
A16: Health | B16: =COUNTIF('Test Cases'!$B$2:$B$1000,$A16) -> 2 | C16: =COUNTIFS('Test Cases'!$B$2:$B$1000,$A16,'Test Cases'!$I$2:$I$1000,"Pass") -> 2 | D16: =COUNTIFS('Test Cases'!$B$2:$B$1000,$A16,'Test Cases'!$I$2:$I$1000,"Fail") -> 0
A17: Register | B17: =COUNTIF('Test Cases'!$B$2:$B$1000,$A17) -> 12 | C17: =COUNTIFS('Test Cases'!$B$2:$B$1000,$A17,'Test Cases'!$I$2:$I$1000,"Pass") -> 8 | D17: =COUNTIFS('Test Cases'!$B$2:$B$1000,$A17,'Test Cases'!$I$2:$I$1000,"Fail") -> 4
A18: Login | B18: =COUNTIF('Test Cases'!$B$2:$B$1000,$A18) -> 5 | C18: =COUNTIFS('Test Cases'!$B$2:$B$1000,$A18,'Test Cases'!$I$2:$I$1000,"Pass") -> 5 | D18: =COUNTIFS('Test Cases'!$B$2:$B$1000,$A18,'Test Cases'!$I$2:$I$1000,"Fail") -> 0
A19: Authorization | B19: =COUNTIF('Test Cases'!$B$2:$B$1000,$A19) -> 6 | C19: =COUNTIFS('Test Cases'!$B$2:$B$1000,$A19,'Test Cases'!$I$2:$I$1000,"Pass") -> 4 | D19: =COUNTIFS('Test Cases'!$B$2:$B$1000,$A19,'Test Cases'!$I$2:$I$1000,"Fail") -> 2
A20: Upload | B20: =COUNTIF('Test Cases'!$B$2:$B$1000,$A20) -> 10 | C20: =COUNTIFS('Test Cases'!$B$2:$B$1000,$A20,'Test Cases'!$I$2:$I$1000,"Pass") -> 7 | D20: =COUNTIFS('Test Cases'!$B$2:$B$1000,$A20,'Test Cases'!$I$2:$I$1000,"Fail") -> 3
A21: Read | B21: =COUNTIF('Test Cases'!$B$2:$B$1000,$A21) -> 7 | C21: =COUNTIFS('Test Cases'!$B$2:$B$1000,$A21,'Test Cases'!$I$2:$I$1000,"Pass") -> 7 | D21: =COUNTIFS('Test Cases'!$B$2:$B$1000,$A21,'Test Cases'!$I$2:$I$1000,"Fail") -> 0
A22: Summary | B22: =COUNTIF('Test Cases'!$B$2:$B$1000,$A22) -> 1 | C22: =COUNTIFS('Test Cases'!$B$2:$B$1000,$A22,'Test Cases'!$I$2:$I$1000,"Pass") -> 1 | D22: =COUNTIFS('Test Cases'!$B$2:$B$1000,$A22,'Test Cases'!$I$2:$I$1000,"Fail") -> 0
A23: Isolation | B23: =COUNTIF('Test Cases'!$B$2:$B$1000,$A23) -> 2 | C23: =COUNTIFS('Test Cases'!$B$2:$B$1000,$A23,'Test Cases'!$I$2:$I$1000,"Pass") -> 2 | D23: =COUNTIFS('Test Cases'!$B$2:$B$1000,$A23,'Test Cases'!$I$2:$I$1000,"Fail") -> 0
A24: Delete | B24: =COUNTIF('Test Cases'!$B$2:$B$1000,$A24) -> 3 | C24: =COUNTIFS('Test Cases'!$B$2:$B$1000,$A24,'Test Cases'!$I$2:$I$1000,"Pass") -> 3 | D24: =COUNTIFS('Test Cases'!$B$2:$B$1000,$A24,'Test Cases'!$I$2:$I$1000,"Fail") -> 0
A26: Results by test type
A27: Type | B27: Cases | C27: Pass | D27: Fail
A28: Positive | B28: =COUNTIF('Test Cases'!$D$2:$D$1000,$A28) -> 13 | C28: =COUNTIFS('Test Cases'!$D$2:$D$1000,$A28,'Test Cases'!$I$2:$I$1000,"Pass") -> 13 | D28: =COUNTIFS('Test Cases'!$D$2:$D$1000,$A28,'Test Cases'!$I$2:$I$1000,"Fail") -> 0
A29: Negative | B29: =COUNTIF('Test Cases'!$D$2:$D$1000,$A29) -> 20 | C29: =COUNTIFS('Test Cases'!$D$2:$D$1000,$A29,'Test Cases'!$I$2:$I$1000,"Pass") -> 14 | D29: =COUNTIFS('Test Cases'!$D$2:$D$1000,$A29,'Test Cases'!$I$2:$I$1000,"Fail") -> 6
A30: Boundary | B30: =COUNTIF('Test Cases'!$D$2:$D$1000,$A30) -> 6 | C30: =COUNTIFS('Test Cases'!$D$2:$D$1000,$A30,'Test Cases'!$I$2:$I$1000,"Pass") -> 3 | D30: =COUNTIFS('Test Cases'!$D$2:$D$1000,$A30,'Test Cases'!$I$2:$I$1000,"Fail") -> 3
A31: Security | B31: =COUNTIF('Test Cases'!$D$2:$D$1000,$A31) -> 9 | C31: =COUNTIFS('Test Cases'!$D$2:$D$1000,$A31,'Test Cases'!$I$2:$I$1000,"Pass") -> 9 | D31: =COUNTIFS('Test Cases'!$D$2:$D$1000,$A31,'Test Cases'!$I$2:$I$1000,"Fail") -> 0
A33: Environment: Node 22, Express 4, MongoDB 7 (CI) · Executed with Postman/Newman 6.2 · Oct 2026

Sheet Test Cases
A1: TC ID | B1: Module | C1: Scenario | D1: Type | E1: Steps | F1: Test Data | G1: Expected Result | H1: Actual Result | I1: Status | J1: Bug ID | K1: Postman Request | L1: Priority
A2: TC-01 | B2: Health | C2: API health check | D2: Positive | E2: GET / | F2: — | G2: 200, status 'ok', JSON, < 1 s | H2: 200, status 'ok', 4 ms | I2: Pass | K2: 01 / API is up | L2: High
A3: TC-02 | B3: Health | C3: Unknown route | D3: Negative | E3: GET /does-not-exist | F3: — | G3: 404 'Route not found' | H3: 404 'Route not found' | I3: Pass | K3: 01 / Unknown route returns 404 | L3: Low
A4: TC-03 | B4: Register | C4: Register with valid details | D4: Positive | E4: POST /auth/register | F4: name, new email, Secret@123 | G4: 201, JWT, email in lower case, no password in response | H4: 201, JWT returned, email lowercased, no password | I4: Pass | K4: 02 / Register a new user | L4: High
A5: TC-04 | B5: Register | C5: Duplicate email | D5: Negative | E5: Register same email twice | F5: existing email | G5: 400 'Email already registered' | H5: 400 as expected | I5: Pass | K5: 02 / Duplicate email is rejected | L5: High
A6: TC-05 | B6: Register | C6: Duplicate email in different case | D6: Negative | E6: Register EMAIL in capitals | F6: QA.A…@TEST.COM | G6: 400 (same account) | H6: 400 as expected | I6: Pass | K6: 02 / Duplicate email in different case | L6: High
A7: TC-06 | B7: Register | C7: Missing name | D7: Negative | E7: POST without name | F7: email + password only | G7: 422 'Name, email and password are required.' | H7: 422 as expected | I7: Pass | K7: 02 / Missing name → 422 | L7: Medium
A8: TC-07 | B8: Register | C8: Name with only spaces | D8: Boundary | E8: POST name=' ' | F8: 3 spaces | G8: 422 | H8: 422 as expected | I8: Pass | K8: 02 / Name with only spaces → 422 | L8: Medium
A9: TC-08 | B9: Register | C9: Missing password | D9: Negative | E9: POST without password | F9: name + email | G9: 422 | H9: 422 as expected | I9: Pass | K9: 02 / Missing password → 422 | L9: Medium
A10: TC-09 | B10: Register | C10: Invalid email format | D10: Negative | E10: POST email without @ | F10: kittu.test.com | G10: 422 'Please enter a valid email.' | H10: 422 as expected | I10: Pass | K10: 02 / Invalid email format → 422 | L10: Medium
A11: TC-10 | B11: Register | C11: Malformed JSON body | D11: Negative | E11: POST broken JSON | F11: {"name": "broken", | G11: 400 'Invalid JSON body.' | H11: 400 as expected | I11: Pass | K11: 02 / Malformed JSON → 400 | L11: Medium
A12: TC-11 | B12: Register | C12: Very short password | D12: Boundary | E12: POST password='1' | F12: 1-character password | G12: 422 — password too short | H12: 201 — account created | I12: Fail | J12: BUG-01 | K12: Open Defects / BUG-01 | L12: High
A13: TC-12 | B13: Register | C13: Password sent as a number | D13: Negative | E13: POST password=123456 (number) | F13: 123456 | G13: 422 validation message | H13: 500 'Something went wrong on the server.' | I13: Fail | J13: BUG-02 | K13: Open Defects / BUG-02 | L13: High
A14: TC-13 | B14: Register | C14: Very long name | D14: Boundary | E14: POST 5,000-char name | F14: 'N' x 5000 | G14: 422 — name too long | H14: 201 — 5,000-char name stored | I14: Fail | J14: BUG-03 | K14: Open Defects / BUG-03 | L14: Low
A15: TC-14 | B15: Register | C15: Email with spaces around it | D15: Boundary | E15: POST ' user@test.com ' | F15: leading/trailing spaces | G15: 201 — spaces trimmed (login already trims) | H15: 422 'Please enter a valid email.' | I15: Fail | J15: BUG-04 | K15: Open Defects / BUG-04 | L15: Low
A16: TC-15 | B16: Login | C16: Login with correct credentials | D16: Positive | E16: POST /auth/login | F16: registered email + password | G16: 200, JWT, same user | H16: 200 as expected | I16: Pass | K16: 03 / Login with correct credentials | L16: High
A17: TC-16 | B17: Login | C17: Email in capitals | D17: Positive | E17: Login with EMAIL in capitals | F17: upper-case email | G17: 200 | H17: 200 as expected | I17: Pass | K17: 03 / Login is case-insensitive | L17: Medium
A18: TC-17 | B18: Login | C18: Wrong password | D18: Negative | E18: Login with wrong password | F18: wrong-password | G18: 401 'Invalid email or password.' | H18: 401 as expected | I18: Pass | K18: 03 / Wrong password → 401 | L18: High
A19: TC-18 | B19: Login | C19: Unknown email (user enumeration) | D19: Security | E19: Login with unregistered email | F19: nobody.here@test.com | G19: 401 with the SAME message as wrong password | H19: Same message | I19: Pass | K19: 03 / Unknown email gives the SAME message | L19: High
A20: TC-19 | B20: Login | C20: NoSQL injection in email | D20: Security | E20: email = {"$ne": null} | F20: object instead of string | G20: 401, no login | H20: 401 as expected | I20: Pass | K20: 03 / NoSQL injection in email is blocked | L20: High
A21: TC-20 | B21: Authorization | C21: No token | D21: Security | E21: GET /transactions without header | F21: — | G21: 401 'Login required.' | H21: 401 as expected | I21: Pass | K21: 04 / No token → 401 | L21: High
A22: TC-21 | B22: Authorization | C22: Malformed token | D22: Security | E22: Bearer not.a.token | F22: — | G22: 401 | H22: 401 as expected | I22: Pass | K22: 04 / Malformed token → 401 | L22: High
A23: TC-22 | B23: Authorization | C23: Forged token (wrong secret) | D23: Security | E23: JWT with real user id signed by attacker | F23: HS256, attacker-secret | G23: 401 | H23: 401 as expected | I23: Pass | K23: 04 / Token signed with a wrong secret | L23: High
A24: TC-23 | B24: Authorization | C24: Wrong auth scheme | D24: Security | E24: Authorization: Basic <token> | F24: — | G24: 401 | H24: 401 as expected | I24: Pass | K24: 04 / Basic auth scheme → 401 | L24: Medium
A25: TC-24 | B25: Authorization | C25: Lower-case 'bearer' | D25: Negative | E25: Authorization: bearer <token> | F25: valid token | G25: 200 (schemes are case-insensitive, RFC 7235) | H25: 401 'Login required.' | I25: Fail | J25: BUG-09 | K25: Open Defects / BUG-09 | L25: Low
A26: TC-25 | B26: Authorization | C26: Valid signature, invalid user id | D26: Negative | E26: JWT sub='not-an-object-id' | F26: signed with server secret | G26: 401 | H26: 500 server error | I26: Fail | J26: BUG-08 | K26: Open Defects / BUG-08 | L26: Medium
A27: TC-26 | B27: Upload | C27: Upload a valid statement | D27: Positive | E27: POST /transactions, 4 rows | F27: Swiggy, Salary, Uber, 400-char row | G27: 201, saved = 4 | H27: 201, saved = 4 | I27: Pass | K27: 05 / Upload 4 transactions | L27: High
A28: TC-27 | B28: Upload | C28: Empty transactions list | D28: Negative | E28: POST transactions=[] | F28: [] | G28: 422 'No transactions to save.' | H28: 422 as expected | I28: Pass | K28: 05 / Empty transactions array | L28: Medium
A29: TC-28 | B29: Upload | C29: transactions is not a list | D29: Negative | E29: POST transactions={…} | F29: object | G29: 422 | H29: 422 as expected | I29: Pass | K29: 05 / transactions is not an array | L29: Medium
A30: TC-29 | B30: Upload | C30: Rows without a date | D30: Negative | E30: POST row with no date | F30: {description, debit} | G30: 422 'No valid rows' | H30: 422 as expected | I30: Pass | K30: 05 / Rows without a date | L30: Medium
A31: TC-30 | B31: Upload | C31: Row limit + 1 | D31: Boundary | E31: POST 5,001 rows | F31: limit is 5,000 | G31: 413 'Max 5000 transactions' | H31: 413 as expected | I31: Pass | K31: 05 / 5,001 rows → 413 | L31: Medium
A32: TC-31 | B32: Upload | C32: Body over 2 MB | D32: Boundary | E32: POST ~2.5 MB body | F32: 4,000 x 600-char rows | G32: 413 'Statement too big. Max 2 MB.' | H32: 413 as expected | I32: Pass | K32: 05 / Body over 2 MB → 413 | L32: Medium
A33: TC-32 | B33: Upload | C33: Failed upload keeps old data | D33: Negative | E33: After TC-27…31, GET list | F33: — | G33: Still 4 rows | H33: 4 rows | I33: Pass | K33: 05 / Failed uploads did not touch saved data | L33: High
A34: TC-33 | B34: Upload | C34: Negative amount | D34: Negative | E34: POST debit = -500 | F34: refund row | G34: 422 (or stored as a credit) | H34: 201 — saved with debit 0 and credit 0, amount lost | I34: Fail | J34: BUG-05 | K34: Open Defects / BUG-05 | L34: Medium
A35: TC-34 | B35: Upload | C35: Invalid date text | D35: Negative | E35: POST date = 'hello' | F35: hello | G35: 422 — invalid date | H35: 201 — counted in total but missing from monthly totals | I35: Fail | J35: BUG-06 | K35: Open Defects / BUG-06 | L35: Medium
A36: TC-35 | B36: Upload | C36: Both debit and credit filled | D36: Negative | E36: POST debit 100 + credit 200 | F36: one row | G36: 422 — row must be one or the other | H36: 201 — counted as spend AND income | I36: Fail | J36: BUG-07 | K36: Open Defects / BUG-07 | L36: Low
A37: TC-36 | B37: Read | C37: List transactions | D37: Positive | E37: GET /transactions | F37: after TC-26 | G37: 4 rows, order kept, '120' → 120, empty credit → 0, category 'Others', 300-char cut | H37: All as expected | I37: Pass | K37: 06 / List all transactions | L37: High
A38: TC-37 | B38: Read | C38: Filter type=Debit / Credit | D38: Positive | E38: GET ?type=Debit, ?type=Credit | F38: — | G38: 3 debits / 1 credit | H38: As expected | I38: Pass | K38: 06 / Filter type=Debit, Credit | L38: Medium
A39: TC-38 | B39: Read | C39: Filter by category | D39: Positive | E39: GET ?category=Food, ?category=All | F39: — | G39: 1 row / 4 rows | H39: As expected | I39: Pass | K39: 06 / Filter category | L39: Medium
A40: TC-39 | B40: Read | C40: Unknown filter value | D40: Negative | E40: GET ?type=Refund | F40: — | G40: Ignored, 4 rows | H40: 4 rows | I40: Pass | K40: 06 / Unknown type value is ignored | L40: Low
...

Sheet Defects
A1: Bug ID | B1: Title | C1: Severity | D1: Priority | E1: Found by | F1: Status | G1: Details
A2: BUG-01 | B2: Register accepts a 1-character password | C2: Major | D2: P2 | E2: TC-11 | F2: Open | G2: See BUG_REPORTS.md
A3: BUG-02 | B3: Numeric password crashes the server (HTTP 500) | C3: Major | D3: P1 | E3: TC-12 | F3: Open | G3: See BUG_REPORTS.md
A4: BUG-03 | B4: No maximum length on name (5,000 chars stored) | C4: Minor | D4: P3 | E4: TC-13 | F4: Open | G4: See BUG_REPORTS.md
A5: BUG-04 | B5: Register rejects email with surrounding spaces, login accepts it | C5: Minor | D5: P3 | E5: TC-14 | F5: Open | G5: See BUG_REPORTS.md
A6: BUG-05 | B6: Negative amount silently saved as 0 (money lost from totals) | C6: Major | D6: P2 | E6: TC-33 | F6: Open | G6: See BUG_REPORTS.md
A7: BUG-06 | B7: Invalid date accepted; monthly totals stop matching the total | C7: Major | D7: P2 | E7: TC-34 | F7: Open | G7: See BUG_REPORTS.md
A8: BUG-07 | B8: Row with both debit and credit counted as spend and income | C8: Minor | D8: P3 | E8: TC-35 | F8: Open | G8: See BUG_REPORTS.md
A9: BUG-08 | B9: Token with non-ObjectId user id crashes (HTTP 500) | C9: Major | D9: P2 | E9: TC-25 | F9: Open | G9: See BUG_REPORTS.md
A10: BUG-09 | B10: Lower-case 'bearer' auth scheme rejected | C10: Minor | D10: P3 | E10: TC-24 | F10: Open | G10: See BUG_REPORTS.md
